<?xml version="1.0"?>
<robot xmlns:xacro="http://www.ros.org/wiki/xacro">

    <xacro:include filename="$(find machine_vision_part2)/urdf/ddrobot/xacro/transmissions.xacro"/>

    <xacro:property name="wheel_mass" value="0.015" />
    <xacro:property name="wheel_radius" value="0.2" />
    <xacro:property name="wheel_height" value="0.1" />
    <xacro:property name="wheel_inertia_calc" value="${(1/12) * wheel_mass * ((3 * (wheel_radius * wheel_radius)) + (wheel_height * wheel_height))}" />
    <xacro:property name="wheel_inertia_calc_izz" value="${(1/2) * wheel_mass * (wheel_radius * wheel_radius)}" />

    <xacro:macro name="wheel" params="side position offset_x offset_y">
        <link name="${side}_${position}_wheel">
            <visual>
                <origin xyz="0 0 0" rpy="${pi/2} 0 0"/>
                <geometry>
                    <cylinder radius="${wheel_radius}" length="${wheel_height}"/>
                </geometry>
                <material name="black"/>
            </visual>
            <collision>
                <origin xyz="0 0 0" rpy="${pi/2} 0 0"/>
                <geometry>
                    <cylinder radius="${wheel_radius}" length="${wheel_height}"/>
                </geometry>
            </collision>
            <inertial>
                <mass value="${wheel_mass}"/>
                <inertia ixx="${wheel_inertia_calc}" ixy="0.0" ixz="0.0" iyy="${wheel_inertia_calc}" iyz="0.0" izz="${wheel_inertia_calc_izz}"/>
            </inertial>  
        </link>
        <joint name="joint_${side}_${position}_wheel" type="continuous">
            <parent link="chasis"/>
            <child link="${side}_${position}_wheel"/>
            <origin xyz="${offset_x} ${offset_y} 0.0" rpy="0.0 0.0 0.0"/>
            <axis xyz="0.0 1 0.0"/>
        </joint>

        <!-- Robot Joints' Transmission -->
        <xacro:wheel_transmission wheelJointName="joint_${side}_${position}_wheel"  />
    </xacro:macro>
</robot>
