<?xml version="1.0" ?>
<!-- =================================================================================== -->
<!-- |    This document was autogenerated by xacro from robot.xacro                    | -->
<!-- |    EDITING THIS FILE BY HAND IS NOT RECOMMENDED                                 | -->
<!-- =================================================================================== -->
<robot name="ddrobot">
  <material name="black">
    <color rgba="0 0 0 1"/>
  </material>
  <material name="red">
    <color rgba="1 0 0 1"/>
  </material>
  <!-- Reference to robot links -->
  <gazebo reference="chasis">
    <material>Gazebo/Red</material>
  </gazebo>
  <gazebo reference="right_front_wheel">
    <mu1 value="200.0"/>
    <mu2 value="100.0"/>
    <kp value="10000000.0"/>
    <kd value="1.0"/>
    <material>Gazebo/Black</material>
  </gazebo>
  <gazebo reference="right_back_wheel">
    <mu1 value="200.0"/>
    <mu2 value="100.0"/>
    <kp value="10000000.0"/>
    <kd value="1.0"/>
    <material>Gazebo/Black</material>
  </gazebo>
  <gazebo reference="left_front_wheel">
    <mu1 value="200.0"/>
    <mu2 value="100.0"/>
    <kp value="10000000.0"/>
    <kd value="1.0"/>
    <material>Gazebo/Black</material>
  </gazebo>
  <gazebo reference="left_back_wheel">
    <mu1 value="200.0"/>
    <mu2 value="100.0"/>
    <kp value="10000000.0"/>
    <kd value="1.0"/>
    <material>Gazebo/Black</material>
  </gazebo>
  <!-- Gazebo Plugins -->
  <gazebo>
    <plugin filename="libgazebo_ros_control.so" name="gazebo_ros_control"/>
  </gazebo>
  <!-- Robot Base Footprint -->
  <link name="base_footprint"/>
  <link name="chasis">
    <!-- Robot Head -->
    <visual>
      <origin rpy="0.0 0.0 0.0" xyz="0.3 0 0.25"/>
      <geometry>
        <sphere radius="0.15"/>
      </geometry>
      <material name="red"/>
    </visual>
    <collision>
      <origin rpy="0.0 0.0 0.0" xyz="0.3 0 0.25"/>
      <geometry>
        <sphere radius="0.15"/>
      </geometry>
    </collision>
    <inertial>
      <mass value="0.1"/>
      <inertia ixx="0.0018000000000000004" ixy="0.0" ixz="0.0" iyy="0.0018000000000000004" iyz="0.0" izz="0.0018000000000000004"/>
    </inertial>
    <!-- Main Robot Body -->
    <visual>
      <origin rpy="0.0 0.0 0.0" xyz="0.0 0.0 0.0"/>
      <geometry>
        <box size="1 0.8 0.25"/>
      </geometry>
      <material name="red"/>
    </visual>
    <collision>
      <origin rpy="0.0 0.0 0.0" xyz="0.0 0.0 0.0"/>
      <geometry>
        <box size="1 0.8 0.25"/>
      </geometry>
    </collision>
    <inertial>
      <mass value="0.1"/>
      <inertia ixx="0.008854166666666666" ixy="0.0" ixz="0.0" iyy="0.005854166666666667" iyz="0.0" izz="0.013666666666666667"/>
    </inertial>
  </link>
  <joint name="joint_base_footprint__chasis" type="fixed">
    <origin rpy="0 0 0" xyz="0 0 0"/>
    <parent link="base_footprint"/>
    <child link="chasis"/>
  </joint>
  <link name="right_front_wheel">
    <visual>
      <origin rpy="1.5707963267948966 0 0" xyz="0 0 0"/>
      <geometry>
        <cylinder length="0.1" radius="0.2"/>
      </geometry>
      <material name="black"/>
    </visual>
    <collision>
      <origin rpy="1.5707963267948966 0 0" xyz="0 0 0"/>
      <geometry>
        <cylinder length="0.1" radius="0.2"/>
      </geometry>
    </collision>
    <inertial>
      <mass value="0.015"/>
      <inertia ixx="0.00016250000000000002" ixy="0.0" ixz="0.0" iyy="0.00016250000000000002" iyz="0.0" izz="0.00030000000000000003"/>
    </inertial>
  </link>
  <joint name="joint_right_front_wheel" type="continuous">
    <parent link="chasis"/>
    <child link="right_front_wheel"/>
    <origin rpy="0.0 0.0 0.0" xyz="0.4 0.45 0.0"/>
    <axis xyz="0.0 1 0.0"/>
  </joint>
  <transmission name="transmission_joint_right_front_wheel">
    <type>transmission_interface/SimpleTransmission</type>
    <joint name="joint_right_front_wheel">
      <hardwareInterface>hardware_interface/VelocityJointInterface</hardwareInterface>
    </joint>
    <actuator name="motor_joint_right_front_wheel">
      <mechanicalReduction>1</mechanicalReduction>
    </actuator>
  </transmission>
  <link name="left_front_wheel">
    <visual>
      <origin rpy="1.5707963267948966 0 0" xyz="0 0 0"/>
      <geometry>
        <cylinder length="0.1" radius="0.2"/>
      </geometry>
      <material name="black"/>
    </visual>
    <collision>
      <origin rpy="1.5707963267948966 0 0" xyz="0 0 0"/>
      <geometry>
        <cylinder length="0.1" radius="0.2"/>
      </geometry>
    </collision>
    <inertial>
      <mass value="0.015"/>
      <inertia ixx="0.00016250000000000002" ixy="0.0" ixz="0.0" iyy="0.00016250000000000002" iyz="0.0" izz="0.00030000000000000003"/>
    </inertial>
  </link>
  <joint name="joint_left_front_wheel" type="continuous">
    <parent link="chasis"/>
    <child link="left_front_wheel"/>
    <origin rpy="0.0 0.0 0.0" xyz="0.4 -0.45 0.0"/>
    <axis xyz="0.0 1 0.0"/>
  </joint>
  <transmission name="transmission_joint_left_front_wheel">
    <type>transmission_interface/SimpleTransmission</type>
    <joint name="joint_left_front_wheel">
      <hardwareInterface>hardware_interface/VelocityJointInterface</hardwareInterface>
    </joint>
    <actuator name="motor_joint_left_front_wheel">
      <mechanicalReduction>1</mechanicalReduction>
    </actuator>
  </transmission>
  <link name="right_back_wheel">
    <visual>
      <origin rpy="1.5707963267948966 0 0" xyz="0 0 0"/>
      <geometry>
        <cylinder length="0.1" radius="0.2"/>
      </geometry>
      <material name="black"/>
    </visual>
    <collision>
      <origin rpy="1.5707963267948966 0 0" xyz="0 0 0"/>
      <geometry>
        <cylinder length="0.1" radius="0.2"/>
      </geometry>
    </collision>
    <inertial>
      <mass value="0.015"/>
      <inertia ixx="0.00016250000000000002" ixy="0.0" ixz="0.0" iyy="0.00016250000000000002" iyz="0.0" izz="0.00030000000000000003"/>
    </inertial>
  </link>
  <joint name="joint_right_back_wheel" type="continuous">
    <parent link="chasis"/>
    <child link="right_back_wheel"/>
    <origin rpy="0.0 0.0 0.0" xyz="-0.4 0.45 0.0"/>
    <axis xyz="0.0 1 0.0"/>
  </joint>
  <transmission name="transmission_joint_right_back_wheel">
    <type>transmission_interface/SimpleTransmission</type>
    <joint name="joint_right_back_wheel">
      <hardwareInterface>hardware_interface/VelocityJointInterface</hardwareInterface>
    </joint>
    <actuator name="motor_joint_right_back_wheel">
      <mechanicalReduction>1</mechanicalReduction>
    </actuator>
  </transmission>
  <link name="left_back_wheel">
    <visual>
      <origin rpy="1.5707963267948966 0 0" xyz="0 0 0"/>
      <geometry>
        <cylinder length="0.1" radius="0.2"/>
      </geometry>
      <material name="black"/>
    </visual>
    <collision>
      <origin rpy="1.5707963267948966 0 0" xyz="0 0 0"/>
      <geometry>
        <cylinder length="0.1" radius="0.2"/>
      </geometry>
    </collision>
    <inertial>
      <mass value="0.015"/>
      <inertia ixx="0.00016250000000000002" ixy="0.0" ixz="0.0" iyy="0.00016250000000000002" iyz="0.0" izz="0.00030000000000000003"/>
    </inertial>
  </link>
  <joint name="joint_left_back_wheel" type="continuous">
    <parent link="chasis"/>
    <child link="left_back_wheel"/>
    <origin rpy="0.0 0.0 0.0" xyz="-0.4 -0.45 0.0"/>
    <axis xyz="0.0 1 0.0"/>
  </joint>
  <transmission name="transmission_joint_left_back_wheel">
    <type>transmission_interface/SimpleTransmission</type>
    <joint name="joint_left_back_wheel">
      <hardwareInterface>hardware_interface/VelocityJointInterface</hardwareInterface>
    </joint>
    <actuator name="motor_joint_left_back_wheel">
      <mechanicalReduction>1</mechanicalReduction>
    </actuator>
  </transmission>
</robot>

