<?xml version="1.0" ?>
<!-- =================================================================================== -->
<!-- |    This document was autogenerated by xacro from xacro/robot.xacro              | -->
<!-- |    EDITING THIS FILE BY HAND IS NOT RECOMMENDED                                 | -->
<!-- =================================================================================== -->
<robot name="ddrobot">
  <material name="black">
    <color rgba="0 0 0 1"/>
  </material>
  <material name="yellow">
    <color rgba="1 1 0 1"/>
  </material>
  <gazebo reference="chasis">
    <material>Gazebo/Yellow</material>
  </gazebo>
  <gazebo reference="right_wheel">
    <material>Gazebo/Black</material>
  </gazebo>
  <gazebo reference="left_wheel">
    <material>Gazebo/Black</material>
  </gazebo>
  <!-- Robot Base Footprint -->
  <link name="base_footprint"/>
  <link name="chasis">
    <!-- Main Robot Body -->
    <visual>
      <origin rpy="0.0 0.0 0.0" xyz="0.0 0.0 0.0"/>
      <geometry>
        <cylinder length="0.15" radius="0.4"/>
      </geometry>
      <material name="yellow"/>
    </visual>
    <collision>
      <origin rpy="0.0 0.0 0.0" xyz="0.0 0.0 0.0"/>
      <geometry>
        <cylinder length="0.15" radius="0.4"/>
      </geometry>
    </collision>
    <inertial>
      <mass value="5"/>
      <inertia ixx="0.209375" ixy="0.0" ixz="0.0" iyy="0.209375" iyz="0.0" izz="0.4000000000000001"/>
    </inertial>
    <!-- Caster -->
    <visual name="caster">
      <origin rpy="0 0 0" xyz="0.2 0 -0.125"/>
      <geometry>
        <sphere radius="0.05"/>
      </geometry>
      <material name="yellow"/>
    </visual>
    <collision>
      <origin rpy="0 0 0" xyz="0.2 0 -0.125"/>
      <geometry>
        <sphere radius="0.05"/>
      </geometry>
    </collision>
    <inertial>
      <mass value="0.5"/>
      <inertia ixx="0.0005000000000000001" ixy="0.0" ixz="0.0" iyy="0.0005000000000000001" iyz="0.0" izz="0.0005000000000000001"/>
    </inertial>
  </link>
  <joint name="joint_base_footprint__chasis" type="fixed">
    <origin rpy="0 0 0" xyz="0 0 0"/>
    <parent link="base_footprint"/>
    <child link="chasis"/>
  </joint>
  <link name="left_wheel">
    <visual>
      <origin rpy="1.5707963267948966 0.0 0.0" xyz="0.0 0.0 0.0"/>
      <geometry>
        <cylinder length="0.1" radius="0.2"/>
      </geometry>
      <material name="black"/>
    </visual>
    <collision>
      <origin rpy="1.5707963267948966 0.0 0.0" xyz="0.0 0.0 0.0"/>
      <geometry>
        <cylinder length="0.1" radius="0.2"/>
      </geometry>
    </collision>
    <inertial>
      <mass value="0.5"/>
      <inertia ixx="0.005416666666666668" ixy="0.0" ixz="0.0" iyy="0.005416666666666668" iyz="0.0" izz="0.010000000000000002"/>
    </inertial>
  </link>
  <joint name="joint_left_wheel" type="continuous">
    <parent link="chasis"/>
    <child link="left_wheel"/>
    <origin rpy="0.0 0.0 0.0" xyz="0.0 0.45 0.0"/>
    <axis xyz="0.0 1 0.0"/>
  </joint>
  <link name="right_wheel">
    <visual>
      <origin rpy="1.5707963267948966 0.0 0.0" xyz="0.0 0.0 0.0"/>
      <geometry>
        <cylinder length="0.1" radius="0.2"/>
      </geometry>
      <material name="black"/>
    </visual>
    <collision>
      <origin rpy="1.5707963267948966 0.0 0.0" xyz="0.0 0.0 0.0"/>
      <geometry>
        <cylinder length="0.1" radius="0.2"/>
      </geometry>
    </collision>
    <inertial>
      <mass value="0.5"/>
      <inertia ixx="0.005416666666666668" ixy="0.0" ixz="0.0" iyy="0.005416666666666668" iyz="0.0" izz="0.010000000000000002"/>
    </inertial>
  </link>
  <joint name="joint_right_wheel" type="continuous">
    <parent link="chasis"/>
    <child link="right_wheel"/>
    <origin rpy="0.0 0.0 0.0" xyz="0.0 -0.45 0.0"/>
    <axis xyz="0.0 1 0.0"/>
  </joint>
</robot>

