<sdf version='1.7'>
  <model name='ddrobot'>
    <link name='base_footprint'>
      <inertial>
        <pose>0 0 0 0 -0 0</pose>
        <mass>0.1</mass>
        <inertia>
          <ixx>0.0018</ixx>
          <ixy>0</ixy>
          <ixz>0</ixz>
          <iyy>0.0018</iyy>
          <iyz>0</iyz>
          <izz>0.0018</izz>
        </inertia>
      </inertial>
      <collision name='base_footprint_fixed_joint_lump__chasis_collision'>
        <pose>0.3 0 0.25 0 -0 0</pose>
        <geometry>
          <sphere>
            <radius>0.15</radius>
          </sphere>
        </geometry>
        <surface>
          <contact>
            <ode/>
          </contact>
          <friction>
            <ode/>
          </friction>
        </surface>
      </collision>
      <collision name='base_footprint_fixed_joint_lump__chasis_collision_1'>
        <pose>0 0 0 0 -0 0</pose>
        <geometry>
          <box>
            <size>1 0.8 0.25</size>
          </box>
        </geometry>
        <surface>
          <contact>
            <ode/>
          </contact>
          <friction>
            <ode/>
          </friction>
        </surface>
      </collision>
      <visual name='base_footprint_fixed_joint_lump__chasis_visual'>
        <pose>0.3 0 0.25 0 -0 0</pose>
        <geometry>
          <sphere>
            <radius>0.15</radius>
          </sphere>
        </geometry>
        <material>
          <script>
            <name>Gazebo/Red</name>
            <uri>file://media/materials/scripts/gazebo.material</uri>
          </script>
        </material>
      </visual>
      <visual name='base_footprint_fixed_joint_lump__chasis_visual_1'>
        <pose>0 0 0 0 -0 0</pose>
        <geometry>
          <box>
            <size>1 0.8 0.25</size>
          </box>
        </geometry>
        <material>
          <script>
            <name>Gazebo/Red</name>
            <uri>file://media/materials/scripts/gazebo.material</uri>
          </script>
        </material>
      </visual>
    </link>
    <joint name='joint_left_back_wheel' type='revolute'>
      <pose relative_to='base_footprint'>-0.4 -0.45 0 0 -0 0</pose>
      <parent>base_footprint</parent>
      <child>left_back_wheel</child>
      <axis>
        <xyz>0 1 0</xyz>
        <limit>
          <lower>-1e+16</lower>
          <upper>1e+16</upper>
        </limit>
        <dynamics>
          <spring_reference>0</spring_reference>
          <spring_stiffness>0</spring_stiffness>
        </dynamics>
      </axis>
    </joint>
    <link name='left_back_wheel'>
      <pose relative_to='joint_left_back_wheel'>0 0 0 0 -0 0</pose>
      <inertial>
        <pose>0 0 0 0 -0 0</pose>
        <mass>0.015</mass>
        <inertia>
          <ixx>0.0001625</ixx>
          <ixy>0</ixy>
          <ixz>0</ixz>
          <iyy>0.0001625</iyy>
          <iyz>0</iyz>
          <izz>0.0003</izz>
        </inertia>
      </inertial>
      <collision name='left_back_wheel_collision'>
        <pose>0 0 0 1.5708 -0 0</pose>
        <geometry>
          <cylinder>
            <length>0.1</length>
            <radius>0.2</radius>
          </cylinder>
        </geometry>
        <surface>
          <contact>
            <ode>
              <kp>1e+07</kp>
              <kd>1</kd>
            </ode>
          </contact>
          <friction>
            <ode>
              <mu>200</mu>
              <mu2>100</mu2>
            </ode>
          </friction>
        </surface>
      </collision>
      <visual name='left_back_wheel_visual'>
        <pose>0 0 0 1.5708 -0 0</pose>
        <geometry>
          <cylinder>
            <length>0.1</length>
            <radius>0.2</radius>
          </cylinder>
        </geometry>
        <material>
          <script>
            <name>Gazebo/Black</name>
            <uri>file://media/materials/scripts/gazebo.material</uri>
          </script>
        </material>
      </visual>
    </link>
    <joint name='joint_left_front_wheel' type='revolute'>
      <pose relative_to='base_footprint'>0.4 -0.45 0 0 -0 0</pose>
      <parent>base_footprint</parent>
      <child>left_front_wheel</child>
      <axis>
        <xyz>0 1 0</xyz>
        <limit>
          <lower>-1e+16</lower>
          <upper>1e+16</upper>
        </limit>
        <dynamics>
          <spring_reference>0</spring_reference>
          <spring_stiffness>0</spring_stiffness>
        </dynamics>
      </axis>
    </joint>
    <link name='left_front_wheel'>
      <pose relative_to='joint_left_front_wheel'>0 0 0 0 -0 0</pose>
      <inertial>
        <pose>0 0 0 0 -0 0</pose>
        <mass>0.015</mass>
        <inertia>
          <ixx>0.0001625</ixx>
          <ixy>0</ixy>
          <ixz>0</ixz>
          <iyy>0.0001625</iyy>
          <iyz>0</iyz>
          <izz>0.0003</izz>
        </inertia>
      </inertial>
      <collision name='left_front_wheel_collision'>
        <pose>0 0 0 1.5708 -0 0</pose>
        <geometry>
          <cylinder>
            <length>0.1</length>
            <radius>0.2</radius>
          </cylinder>
        </geometry>
        <surface>
          <contact>
            <ode>
              <kp>1e+07</kp>
              <kd>1</kd>
            </ode>
          </contact>
          <friction>
            <ode>
              <mu>200</mu>
              <mu2>100</mu2>
            </ode>
          </friction>
        </surface>
      </collision>
      <visual name='left_front_wheel_visual'>
        <pose>0 0 0 1.5708 -0 0</pose>
        <geometry>
          <cylinder>
            <length>0.1</length>
            <radius>0.2</radius>
          </cylinder>
        </geometry>
        <material>
          <script>
            <name>Gazebo/Black</name>
            <uri>file://media/materials/scripts/gazebo.material</uri>
          </script>
        </material>
      </visual>
    </link>
    <joint name='joint_right_back_wheel' type='revolute'>
      <pose relative_to='base_footprint'>-0.4 0.45 0 0 -0 0</pose>
      <parent>base_footprint</parent>
      <child>right_back_wheel</child>
      <axis>
        <xyz>0 1 0</xyz>
        <limit>
          <lower>-1e+16</lower>
          <upper>1e+16</upper>
        </limit>
        <dynamics>
          <spring_reference>0</spring_reference>
          <spring_stiffness>0</spring_stiffness>
        </dynamics>
      </axis>
    </joint>
    <link name='right_back_wheel'>
      <pose relative_to='joint_right_back_wheel'>0 0 0 0 -0 0</pose>
      <inertial>
        <pose>0 0 0 0 -0 0</pose>
        <mass>0.015</mass>
        <inertia>
          <ixx>0.0001625</ixx>
          <ixy>0</ixy>
          <ixz>0</ixz>
          <iyy>0.0001625</iyy>
          <iyz>0</iyz>
          <izz>0.0003</izz>
        </inertia>
      </inertial>
      <collision name='right_back_wheel_collision'>
        <pose>0 0 0 1.5708 -0 0</pose>
        <geometry>
          <cylinder>
            <length>0.1</length>
            <radius>0.2</radius>
          </cylinder>
        </geometry>
        <surface>
          <contact>
            <ode>
              <kp>1e+07</kp>
              <kd>1</kd>
            </ode>
          </contact>
          <friction>
            <ode>
              <mu>200</mu>
              <mu2>100</mu2>
            </ode>
          </friction>
        </surface>
      </collision>
      <visual name='right_back_wheel_visual'>
        <pose>0 0 0 1.5708 -0 0</pose>
        <geometry>
          <cylinder>
            <length>0.1</length>
            <radius>0.2</radius>
          </cylinder>
        </geometry>
        <material>
          <script>
            <name>Gazebo/Black</name>
            <uri>file://media/materials/scripts/gazebo.material</uri>
          </script>
        </material>
      </visual>
    </link>
    <joint name='joint_right_front_wheel' type='revolute'>
      <pose relative_to='base_footprint'>0.4 0.45 0 0 -0 0</pose>
      <parent>base_footprint</parent>
      <child>right_front_wheel</child>
      <axis>
        <xyz>0 1 0</xyz>
        <limit>
          <lower>-1e+16</lower>
          <upper>1e+16</upper>
        </limit>
        <dynamics>
          <spring_reference>0</spring_reference>
          <spring_stiffness>0</spring_stiffness>
        </dynamics>
      </axis>
    </joint>
    <link name='right_front_wheel'>
      <pose relative_to='joint_right_front_wheel'>0 0 0 0 -0 0</pose>
      <inertial>
        <pose>0 0 0 0 -0 0</pose>
        <mass>0.015</mass>
        <inertia>
          <ixx>0.0001625</ixx>
          <ixy>0</ixy>
          <ixz>0</ixz>
          <iyy>0.0001625</iyy>
          <iyz>0</iyz>
          <izz>0.0003</izz>
        </inertia>
      </inertial>
      <collision name='right_front_wheel_collision'>
        <pose>0 0 0 1.5708 -0 0</pose>
        <geometry>
          <cylinder>
            <length>0.1</length>
            <radius>0.2</radius>
          </cylinder>
        </geometry>
        <surface>
          <contact>
            <ode>
              <kp>1e+07</kp>
              <kd>1</kd>
            </ode>
          </contact>
          <friction>
            <ode>
              <mu>200</mu>
              <mu2>100</mu2>
            </ode>
          </friction>
        </surface>
      </collision>
      <visual name='right_front_wheel_visual'>
        <pose>0 0 0 1.5708 -0 0</pose>
        <geometry>
          <cylinder>
            <length>0.1</length>
            <radius>0.2</radius>
          </cylinder>
        </geometry>
        <material>
          <script>
            <name>Gazebo/Black</name>
            <uri>file://media/materials/scripts/gazebo.material</uri>
          </script>
        </material>
      </visual>
    </link>
    <static>0</static>
    <plugin name='gazebo_ros_control' filename='libgazebo_ros_control.so'/>
  </model>
</sdf>
