<?xml version="1.0" ?>
<!-- =================================================================================== -->
<!-- |    This document was autogenerated by xacro from robot.xacro                    | -->
<!-- |    EDITING THIS FILE BY HAND IS NOT RECOMMENDED                                 | -->
<!-- =================================================================================== -->
<robot name="ddrobot">
  <material name="black">
    <color rgba="0 0 0 1"/>
  </material>
  <material name="red">
    <color rgba="1 0 0 1"/>
  </material>
  <gazebo reference="chasis">
    <material>Gazebo/Red</material>
  </gazebo>
  <gazebo reference="right_wheel">
    <material>Gazebo/Black</material>
  </gazebo>
  <gazebo reference="left_wheel">
    <material>Gazebo/Black</material>
  </gazebo>
  <!-- Robot Base Footprint -->
  <link name="base_footprint"/>
  <link name="chasis">
    <!-- Main Robot Body -->
    <visual>
      <origin rpy="0.0 0.0 0.0" xyz="0.0 0.0 0.0"/>
      <geometry>
        <cylinder length="0.025" radius="0.0825"/>
      </geometry>
      <material name="red"/>
    </visual>
    <collision>
      <origin rpy="0.0 0.0 0.0" xyz="0.0 0.0 0.0"/>
      <geometry>
        <cylinder length="0.025" radius="0.0825"/>
      </geometry>
    </collision>
    <inertial>
      <mass value="0.1"/>
      <inertia ixx="0.00017536458333333336" ixy="0.0" ixz="0.0" iyy="0.00017536458333333336" iyz="0.0" izz="0.00034031250000000007"/>
    </inertial>
    <!-- Passive Wheel Holder -->
    <visual>
      <origin rpy="0 0 0" xyz="0.2 0 -0.075"/>
      <geometry>
        <cylinder length="0.018" radius="0.01"/>
      </geometry>
      <material name="red"/>
    </visual>
    <collision>
      <origin rpy="0 0 0" xyz="0.2 0 -0.075"/>
      <geometry>
        <cylinder length="0.018" radius="0.01"/>
      </geometry>
    </collision>
    <inertial>
      <mass value="0.02"/>
      <inertia ixx="4.665e-06" ixy="0.0" ixz="0.0" iyy="4.665e-06" iyz="0.0" izz="4.665e-06"/>
    </inertial>
    <!-- Passive Wheel -->
    <visual>
      <origin rpy="0 0 0" xyz="0.2 0 -0.15"/>
      <geometry>
        <sphere radius="0.01"/>
      </geometry>
      <material name="red"/>
    </visual>
    <collision>
      <origin rpy="0 0 0" xyz="0.2 0 -0.15"/>
      <geometry>
        <sphere radius="0.01"/>
      </geometry>
    </collision>
    <inertial>
      <mass value="0.02"/>
      <inertia ixx="8.000000000000001e-07" ixy="0.0" ixz="0.0" iyy="8.000000000000001e-07" iyz="0.0" izz="8.000000000000001e-07"/>
    </inertial>
  </link>
  <joint name="joint_base_footprint__chasis" type="fixed">
    <origin rpy="0 0 0" xyz="0 0 0"/>
    <parent link="base_footprint"/>
    <child link="chasis"/>
  </joint>
  <link name="left_wheel">
    <visual>
      <origin rpy="1.5707963267948966 0.0 0.0" xyz="0.0 0.0 0.0"/>
      <geometry>
        <cylinder length="0.008" radius="0.035"/>
      </geometry>
      <material name="black"/>
    </visual>
    <collision>
      <origin rpy="1.5707963267948966 0.0 0.0" xyz="0.0 0.0 0.0"/>
      <geometry>
        <cylinder length="0.008" radius="0.035"/>
      </geometry>
    </collision>
    <inertial>
      <mass value="0.015"/>
      <inertia ixx="4.673749999999999e-06" ixy="0.0" ixz="0.0" iyy="4.673749999999999e-06" iyz="0.0" izz="9.187500000000001e-06"/>
    </inertial>
  </link>
  <joint name="joint_left_wheel" type="continuous">
    <parent link="chasis"/>
    <child link="left_wheel"/>
    <origin rpy="0.0 0.0 0.0" xyz="0.0 0.45 0.0"/>
    <axis xyz="0.0 1 0.0"/>
  </joint>
  <link name="right_wheel">
    <visual>
      <origin rpy="1.5707963267948966 0.0 0.0" xyz="0.0 0.0 0.0"/>
      <geometry>
        <cylinder length="0.008" radius="0.035"/>
      </geometry>
      <material name="black"/>
    </visual>
    <collision>
      <origin rpy="1.5707963267948966 0.0 0.0" xyz="0.0 0.0 0.0"/>
      <geometry>
        <cylinder length="0.008" radius="0.035"/>
      </geometry>
    </collision>
    <inertial>
      <mass value="0.015"/>
      <inertia ixx="4.673749999999999e-06" ixy="0.0" ixz="0.0" iyy="4.673749999999999e-06" iyz="0.0" izz="9.187500000000001e-06"/>
    </inertial>
  </link>
  <joint name="joint_right_wheel" type="continuous">
    <parent link="chasis"/>
    <child link="right_wheel"/>
    <origin rpy="0.0 0.0 0.0" xyz="0.0 -0.45 0.0"/>
    <axis xyz="0.0 1 0.0"/>
  </joint>
</robot>

