<?xml version="1.0" ?>
<!-- =================================================================================== -->
<!-- |    This document was autogenerated by xacro from robot.xacro                    | -->
<!-- |    EDITING THIS FILE BY HAND IS NOT RECOMMENDED                                 | -->
<!-- =================================================================================== -->
<robot name="ddrobot">
  <material name="black">
    <color rgba="0 0 0 1"/>
  </material>
  <material name="yellow">
    <color rgba="1 1 0 1"/>
  </material>
  <gazebo reference="chasis">
    <material>Gazebo/RedBright</material>
  </gazebo>
  <gazebo reference="right_wheel">
    <material>Gazebo/Black</material>
  </gazebo>
  <gazebo reference="left_wheel">
    <material>Gazebo/Black</material>
  </gazebo>
  <!-- Robot Base Footprint -->
  <link name="base_footprint"/>
  <link name="chasis">
    <!-- Main Robot Body -->
    <visual>
      <origin rpy="0.0 0.0 0.0" xyz="0.0 0.0 0.0"/>
      <geometry>
        <cylinder length="0.15" radius="0.4"/>
      </geometry>
      <material name="yellow"/>
    </visual>
    <collision>
      <origin rpy="0.0 0.0 0.0" xyz="0.0 0.0 0.0"/>
      <geometry>
        <cylinder length="0.15" radius="0.4"/>
      </geometry>
    </collision>
    <inertial>
      <mass value="0.1"/>
      <inertia ixx="0.0041875" ixy="0.0" ixz="0.0" iyy="0.0041875" iyz="0.0" izz="0.008000000000000002"/>
    </inertial>
    <!-- Passive Wheel Holder -->
    <visual>
      <origin rpy="0 0 0" xyz="0.2 0 -0.075"/>
      <geometry>
        <cylinder length="0.15" radius="0.05"/>
      </geometry>
      <material name="yellow"/>
    </visual>
    <collision>
      <origin rpy="0 0 0" xyz="0.2 0 -0.075"/>
      <geometry>
        <cylinder length="0.15" radius="0.05"/>
      </geometry>
    </collision>
    <inertial>
      <mass value="0.02"/>
      <inertia ixx="0.0001375" ixy="0.0" ixz="0.0" iyy="0.0001375" iyz="0.0" izz="0.0001375"/>
    </inertial>
    <!-- Passive Wheel -->
    <visual>
      <origin rpy="0 0 0" xyz="0.2 0 -0.15"/>
      <geometry>
        <sphere radius="0.05"/>
      </geometry>
      <material name="yellow"/>
    </visual>
    <collision>
      <origin rpy="0 0 0" xyz="0.2 0 -0.15"/>
      <geometry>
        <sphere radius="0.05"/>
      </geometry>
    </collision>
    <inertial>
      <mass value="0.02"/>
      <inertia ixx="2.0000000000000005e-05" ixy="0.0" ixz="0.0" iyy="2.0000000000000005e-05" iyz="0.0" izz="2.0000000000000005e-05"/>
    </inertial>
  </link>
  <joint name="joint_base_footprint__chasis" type="fixed">
    <origin rpy="0 0 0" xyz="0 0 0"/>
    <parent link="base_footprint"/>
    <child link="chasis"/>
  </joint>
  <link name="left_wheel">
    <visual>
      <origin rpy="1.5707963267948966 0.0 0.0" xyz="0.0 0.0 0.0"/>
      <geometry>
        <cylinder length="0.1" radius="0.2"/>
      </geometry>
      <material name="black"/>
    </visual>
    <collision>
      <origin rpy="1.5707963267948966 0.0 0.0" xyz="0.0 0.0 0.0"/>
      <geometry>
        <cylinder length="0.1" radius="0.2"/>
      </geometry>
    </collision>
    <inertial>
      <mass value="0.015"/>
      <inertia ixx="0.00016250000000000002" ixy="0.0" ixz="0.0" iyy="0.00016250000000000002" iyz="0.0" izz="0.00030000000000000003"/>
    </inertial>
  </link>
  <joint name="joint_left_wheel" type="continuous">
    <parent link="chasis"/>
    <child link="left_wheel"/>
    <origin rpy="0.0 0.0 0.0" xyz="0.0 0.45 0.0"/>
    <axis xyz="0.0 1 0.0"/>
  </joint>
  <link name="right_wheel">
    <visual>
      <origin rpy="1.5707963267948966 0.0 0.0" xyz="0.0 0.0 0.0"/>
      <geometry>
        <cylinder length="0.1" radius="0.2"/>
      </geometry>
      <material name="black"/>
    </visual>
    <collision>
      <origin rpy="1.5707963267948966 0.0 0.0" xyz="0.0 0.0 0.0"/>
      <geometry>
        <cylinder length="0.1" radius="0.2"/>
      </geometry>
    </collision>
    <inertial>
      <mass value="0.015"/>
      <inertia ixx="0.00016250000000000002" ixy="0.0" ixz="0.0" iyy="0.00016250000000000002" iyz="0.0" izz="0.00030000000000000003"/>
    </inertial>
  </link>
  <joint name="joint_right_wheel" type="continuous">
    <parent link="chasis"/>
    <child link="right_wheel"/>
    <origin rpy="0.0 0.0 0.0" xyz="0.0 -0.45 0.0"/>
    <axis xyz="0.0 1 0.0"/>
  </joint>
</robot>

